<?xml version="1.0" ?>
<robot name="ATV">
  <joint name="imu_joint" type="fixed">
    <parent link="base_link"/>
    <child link="imu_link"/>
    <origin rpy="0  0  0" xyz="0  0  0"/>
    <axis xyz="1  0  0"/>
    <limit effort="0.0" lower="0.0" upper="0.0" velocity="0.0"/>
  </joint>
  <joint name="front_left_steering_joint" type="revolute">
    <parent link="base_link"/>
    <child link="front_left_wheel_steering_block"/>
    <origin rpy="1.57079  0       0" xyz="1.20222  0.5      0.35515"/>
    <axis xyz="0  1  0"/>
    <dynamics damping="1" friction="1"/>
    <limit effort="0.0" lower="-0.7727" upper="0.7727" velocity="0.0"/>
  </joint>
  <joint name="front_left_wheel_joint" type="continuous">
    <parent link="front_left_wheel_steering_block"/>
    <child link="front_left_wheel"/>
    <origin rpy="-3.09079  0       0" xyz="0      -0.00818 -0.21562"/>
    <axis xyz="0   0.00083   1"/>
    <dynamics damping="10" friction="5"/>
    <limit effort="0" velocity="0"/>
  </joint>
  <joint name="front_right_steering_joint" type="revolute">
    <parent link="base_link"/>
    <child link="front_right_wheel_steering_block"/>
    <origin rpy="1.57079  0       0" xyz="1.20222 -0.5      0.35515"/>
    <axis xyz="0  1  0"/>
    <dynamics damping="1" friction="1"/>
    <limit effort="1000" lower="-0.7727" upper="0.7727" velocity="5"/>
  </joint>
  <joint name="front_right_wheel_joint" type="continuous">
    <parent link="front_right_wheel_steering_block"/>
    <child link="front_right_wheel"/>
    <origin rpy="-0.05079  0       0" xyz="0      -0.00818  0.21562"/>
    <axis xyz="0   0.000083  -1"/>
    <limit effort="0" velocity="0"/>
    <dynamics damping="10" friction="5"/>
  </joint>
  <joint name="rear_left_wheel_joint" type="continuous">
    <parent link="base_link"/>
    <child link="rear_left_wheel"/>
    <origin rpy="-1.52  0    0" xyz="-0.99377  0.71562  0.34697"/>
    <axis xyz="0   0.00083   1"/>
    <dynamics damping="10" friction="5"/>
    <limit effort="10000" velocity="1000"/>
  </joint>
  <joint name="rear_right_wheel_joint" type="continuous">
    <parent link="base_link"/>
    <child link="rear_right_wheel"/>
    <origin rpy="1.52  0    0" xyz="-0.99377 -0.71562  0.34697"/>
    <axis xyz="0   0.00083  -1"/>
    <dynamics damping="10" friction="5"/>
    <limit effort="10000" velocity="1000"/>
  </joint>
  <!-- <joint name="front_left_rod_joint" type="revolute">
    <parent link="steering_rod"/>
    <child link="steering_rod_left_block"/>
    <origin rpy="1.57079  0       0" xyz="-0.5  0      0"/>
    <axis xyz="0  1  0"/>
    <limit effort="0.0" lower="0" upper="0" velocity="0.0"/>
  </joint>
  <joint name="front_right_rod_joint" type="revolute">
    <parent link="steering_rod"/>
    <child link="steering_rod_right_block"/>
    <origin rpy="1.57079  0       0" xyz="0.5  0      0"/>
    <axis xyz="0  1  0"/>
    <limit effort="0.0" lower="0" upper="0" velocity="0.0"/>
  </joint> -->
  <joint name="front_left_steering_rod_joint" type="continuous">
    <parent link="front_left_wheel_steering_block"/>
    <child link="steering_rod_left_block"/>
    <origin rpy="0  0       0" xyz="-0.5 0 0.11"/>
    <axis xyz="0  1 0"/>
    <limit effort="0.0" lower="0" upper="0" velocity="0.0"/>
  </joint>
  <joint name="front_right_steering_rod_joint" type="continuous">
    <parent link="front_right_wheel_steering_block"/>
    <child link="steering_rod_right_block"/>
    <origin rpy="1.57079  0       0" xyz="-0.5 0 -0.11"/>
    <axis xyz="0  0  1"/>
    <limit effort="0.0" lower="0" upper="0" velocity="0.0"/>
  </joint>
  <joint name="camera_joint" type="revolute">
    <parent link="base_link"/>
    <child link="camera_link"/>
    <axis xyz="0 1 0" />
    <origin xyz="0.35 0 1.9" rpy="0 0 0"/>
    <limit effort="0.0" lower="0" upper="0" velocity="0.0"/>
  </joint>
  <!-- <joint name="front_right_left_steering_rod_joint" type="fixed">
    <parent link="steering_rod_left_block"/>
    <child link="steering_rod_right_block"/>
    <origin rpy="1.57079  0       0" xyz="0  0      0.7"/>
    <axis xyz="0  0  1"/>
    <limit effort="0.0" lower="0" upper="0" velocity="0.0"/>
  </joint> -->
  <gazebo>
    <joint type="fixed" name="front_right_left_steering_rod_joint">
      <child>steering_rod_left_block</child>
      <parent>steering_rod_right_block</parent>
      <axis>
        <xyz>0 1 0</xyz>
        <dynamics>
          <damping>0</damping>
        </dynamics>
        <use_parent_model_frame>true</use_parent_model_frame>
      </axis>
    </joint>
    <joint type="revolute" name="rear_differential_joint">
      <child>rear_right_wheel</child>
      <parent>rear_left_wheel</parent>
      <axis>
        <xyz>0 1 0</xyz>
        <dynamics>
          <damping>70</damping>
        </dynamics>
        <use_parent_model_frame>true</use_parent_model_frame>
      </axis>
      <physics>
        <ode>
          <erp>0</erp>
          <cfm>1000</cfm>
          <cfm_damping>1</cfm_damping>
        </ode>
      </physics>
    </joint>
  </gazebo>
  <!-- <joint name="rear_differential_joint" type="continuous">
    <parent link="rear_left_wheel"/>
    <child link="rear_right_wheel"/>
    <origin rpy="-1.52  0    0" xyz="-0.99377  0.71562  0.34697"/>
    <axis xyz="0   0     1"/>
    <limit effort="0" lower="0" upper="0" velocity="0"/>
  </joint> -->
  <!-- <joint name="gas_joint" type="prismatic">
    <parent link="base_link"/>
    <child link="gas_pedal"/>
    <origin rpy="0  0  0" xyz="0.63     0.1      0.57999"/>
    <axis xyz="0.7071  0     -0.7071"/>
    <limit effort="0.0" lower="0.0" upper="0.08" velocity="0.0"/>
  </joint>
  <joint name="brake_joint" type="prismatic">
    <parent link="base_link"/>
    <child link="brake_pedal"/>
    <origin rpy="0  0  0" xyz="0.64     0.27     0.57999"/>
    <axis xyz="0.85749  0      -0.51449"/>
    <limit effort="0.0" lower="0.0" upper="0.08" velocity="0.0"/>
  </joint>
  <joint name="steering_joint" type="revolute">
    <parent link="base_link"/>
    <child link="steering_wheel"/>
    <origin rpy="0   -0.87  0" xyz="0.42  0.46  1.2"/>
    <axis xyz="0  0  1"/>
    <limit effort="0.0" lower="-3.14" upper="3.14" velocity="0.0"/>
  </joint>
  <joint name="hand_brake_joint" type="revolute">
    <parent link="base_link"/>
    <child link="hand_brake"/>
    <origin rpy="0  0  0" xyz="0.53   0.205  1.05"/>
    <axis xyz="0 -1  0"/>
    <limit effort="0.0" lower="0.0" upper="0.6" velocity="0.0"/>
  </joint>
  <joint name="FNR_switch_joint" type="revolute">
    <parent link="base_link"/>
    <child link="FNR_switch"/>
    <origin rpy="0    0.25  0" xyz="0.54     0.1      1.14999"/>
    <axis xyz="0 -1  0"/>
    <limit effort="0.0" lower="-0.3" upper="0.3" velocity="0.0"/>
  </joint> -->
  <link name="base_link">
    <inertial>
      <mass value="720.0"/>
      <origin rpy="0  0  0" xyz="0.1  0   0.4"/>
      <inertia ixx="140" ixy="0.0" ixz="0.0" iyy="550" iyz="0.0" izz="550"/>
    </inertial>
    <collision name="chassis_bottom">
      <origin rpy="0  0  0" xyz="0.2    0     0.335"/>
      <geometry>
        <box size="1.34 1.65746 0.06"/>
      </geometry>
    </collision>
    <collision name="cargo_bottom">
      <origin rpy="0  0  0" xyz="-1     0     0.921"/>
      <geometry>
        <box size="1.04609 1.6998 0.01"/>
      </geometry>
    </collision>
    <collision name="cargo_front">
      <origin rpy="0  0  0" xyz="-0.495  0     1.06"/>
      <geometry>
        <box size="0.05 1.69982 0.27"/>
      </geometry>
    </collision>
    <collision name="cargo_back">
      <origin rpy="0  0  0" xyz="-1.465  0     1.06"/>
      <geometry>
        <box size="0.05 1.69982 0.27"/>
      </geometry>
    </collision>
    <collision name="cargo_left">
      <origin rpy="0  0  0" xyz="-0.97     0.82491  1.06"/>
      <geometry>
        <box size="1.04609 0.05 0.27"/>
      </geometry>
    </collision>
    <collision name="cargo_right">
      <origin rpy="0  0  0" xyz="-0.97    -0.82491  1.06"/>
      <geometry>
        <box size="1.04609 0.05 0.27"/>
      </geometry>
    </collision>
    <collision name="seat">
      <origin rpy="0  0  0" xyz="0    0    0.62"/>
      <geometry>
        <box size="0.52167 1.37206 0.53369"/>
      </geometry>
    </collision>
    <collision name="mud_seat">
      <origin rpy="0  0  0" xyz="0    0    0.86"/>
      <geometry>
        <box size="0.52167 1.30 0.1"/>
      </geometry>
    </collision>
    <collision name="seat_back">
      <origin rpy="0  -0.2  0" xyz="-0.26   0     1.125"/>
      <geometry>
        <box size="0.06 1.37206 0.6"/>
      </geometry>
    </collision>
    <collision name="engine">
      <origin rpy="0  0  0" xyz="1.12  0    0.7"/>
      <geometry>
        <box size="0.58 1.3 0.8"/>
      </geometry>
    </collision>
    <collision name="rollcage_top_left">
      <origin rpy="3.14159  1.54159  3.14159" xyz="-0.02   0.76   1.936"/>
      <geometry>
        <cylinder length="0.68" radius="0.03"/>
      </geometry>
    </collision>
    <collision name="rollcage_top_right">
      <origin rpy="3.14159  1.54159  3.14159" xyz="-0.02  -0.76   1.936"/>
      <geometry>
        <cylinder length="0.68" radius="0.03"/>
      </geometry>
    </collision>
    <collision name="rollcage_top_front">
      <origin rpy="0 -1  0" xyz="0.315  0     1.93"/>
      <geometry>
        <box size="0.01299 1.54 0.10226"/>
      </geometry>
    </collision>
    <collision name="rollcage_top_back">
      <origin rpy="0  0  0" xyz="-0.41  0    1.88"/>
      <geometry>
        <box size="0.01299 1.54 0.10226"/>
      </geometry>
    </collision>
    <collision name="rollcage_front_left">
      <origin rpy="0   -0.54  0" xyz="0.602  0.755  1.45"/>
      <geometry>
        <cylinder length="1.15" radius="0.03"/>
      </geometry>
    </collision>
    <collision name="rollcage_front_right">
      <origin rpy="0   -0.54  0" xyz="0.602 -0.755  1.45"/>
      <geometry>
        <cylinder length="1.15" radius="0.03"/>
      </geometry>
    </collision>
    <collision name="rollcage_back_left">
      <origin rpy="0  0  0" xyz="-0.4    0.755  1.45"/>
      <geometry>
        <cylinder length="1.00" radius="0.03"/>
      </geometry>
    </collision>
    <collision name="rollcage_back_right">
      <origin rpy="0  0  0" xyz="-0.4   -0.755  1.45"/>
      <geometry>
        <cylinder length="1.00" radius="0.03"/>
      </geometry>
    </collision>
    <collision name="rollcage_X_1">
      <origin rpy="0.397  0     0" xyz="-0.411  0.04   1.445"/>
      <geometry>
        <box size="0.01392 1.557245 0.078"/>
      </geometry>
    </collision>
    <collision name="rollcage_X_2">
      <origin rpy="-0.397  0     0" xyz="-0.4   -0.04   1.445"/>
      <geometry>
        <box size="0.01392 1.557245 0.078"/>
      </geometry>
    </collision>
    <collision name="central_hump1_collision">
      <origin rpy="0  0  0" xyz="0.55 -0.1   0.4"/>
      <geometry>
        <box size="0.6 0.15 0.1"/>
      </geometry>
    </collision>
    <collision name="central_hump2_collision">
      <origin rpy="0  -0.5  0" xyz="0.7  -0.05  0.45"/>
      <geometry>
        <box size="0.20 0.05 0.1"/>
      </geometry>
    </collision>
    <collision name="central_hump3_collision">
      <origin rpy="0  -0.8  0" xyz="0.798 -0.125  0.478"/>
      <geometry>
        <box size="0.129 0.1 0.05"/>
      </geometry>
    </collision>
    <collision name="central_hump4_collision">
      <origin rpy="0  0  0" xyz="0.8135 -0.05    0.45"/>
      <geometry>
        <box size="0.10 0.05 0.1835"/>
      </geometry>
    </collision>
    <collision name="central_hump5_collision">
      <origin rpy="0  0  0" xyz="0.84  -0.125  0.45"/>
      <geometry>
        <box size="0.03 0.1 0.1835"/>
      </geometry>
    </collision>
    <collision name="central_hump6_collision">
      <origin rpy="0  0  0" xyz="0.82  -0.125  0.475"/>
      <geometry>
        <box size="0.03 0.1 0.05"/>
      </geometry>
    </collision>
    <visual name="visual">
      <origin rpy="0       0      -1.57079" xyz="0  0  0"/>
      <geometry>
        <mesh filename="package://atvsim_description/models/ATV/meshes/Body.dae" scale="1.0 1.0 1.0"/>
      </geometry>
    </visual>
    <visual name="cargo_visual">
      <origin rpy="0      0     -1.5707" xyz="-1.2      0      0.87"/>
      <geometry>
        <mesh filename="package://atvsim_description/models/ATV/meshes/Bed.dae" scale="1.0 1.0 1.0"/>
      </geometry>
    </visual>
    <visual name="tailgate_visual">
      <origin rpy="0      0     -1.5707" xyz="-1.492  0     0.9"/>
      <geometry>
        <mesh filename="package://atvsim_description/models/ATV/meshes/Tail_Gate.dae" scale="1.0 1.0 1.0"/>
      </geometry>
    </visual>
    <visual name="front_left_brake_visual">
      <origin rpy="3.1415  0      1.5707" xyz="1.12    -0.57487  0.35516"/>
      <geometry>
        <mesh filename="package://atvsim_description/models/ATV/meshes/Brake_Front_Left.dae" scale="1.0 1.0 1.0"/>
      </geometry>
    </visual>
    <visual name="front_right_brake_visual">
      <origin rpy="3.1415  0      1.5707" xyz="2.58     0.05  0.8"/>
      <geometry>
        <mesh filename="package://atvsim_description/models/ATV/meshes/Brake_Front_Right.dae" scale="1.0 1.0 1.0"/>
      </geometry>
    </visual>
    <visual name="central_hump1">
      <origin rpy="0  0  0" xyz="0.55 -0.1   0.4"/>
      <geometry>
        <box size="0.6 0.15 0.1"/>
      </geometry>
    </visual>
    <visual name="central_hump2">
      <origin rpy="0  -0.5  0" xyz="0.7  -0.05  0.45"/>
      <geometry>
        <box size="0.20 0.05 0.1"/>
      </geometry>
    </visual>
    <visual name="central_hump3">
      <origin rpy="0  -0.8  0" xyz="0.798 -0.125  0.478"/>
      <geometry>
        <box size="0.129 0.1 0.05"/>
      </geometry>
    </visual>
    <visual name="central_hump4">
      <origin rpy="0  0  0" xyz="0.8135 -0.05    0.45"/>
      <geometry>
        <box size="0.10 0.05 0.1835"/>
      </geometry>
    </visual>
    <visual name="central_hump5">
      <origin rpy="0  0  0" xyz="0.84  -0.125  0.45"/>
      <geometry>
        <box size="0.03 0.1 0.1835"/>
      </geometry>
    </visual>
    <visual name="central_hump6">
      <origin rpy="0  0  0" xyz="0.82  -0.125  0.475"/>
      <geometry>
        <box size="0.03 0.1 0.05"/>
      </geometry>
    </visual>
  </link>
  <link name="imu_link">
    <inertial>
      <mass value="0.015"/>
      <origin rpy="0  0  0" xyz="0  0  0"/>
      <inertia ixx="1e-05" ixy="0" ixz="0" iyy="1e-05" iyz="0" izz="1e-05"/>
    </inertial>
  </link>
  <link name="front_left_wheel">
    <inertial>
      <mass value="12"/>
      <origin rpy="0  0  0" xyz="0  0  0"/>
      <inertia ixx="0.5" ixy="0.0" ixz="0.0" iyy="0.5" iyz="0.0" izz="1.0"/>
    </inertial>
    <collision name="collision">
      <origin rpy="0  0  0" xyz="0  0  0"/>
      <geometry>
        <cylinder length="0.2794" radius="0.3175"/>
      </geometry>
    </collision>
    <visual name="tire_visual">
      <origin rpy="0  1.57079  0" xyz="0  0  -0.13"/>
      <geometry>
        <mesh filename="package://atvsim_description/models/ATV/meshes/Wheel_Front_Left.dae" scale="1.003700111 0.886200464 0.886200464"/>
      </geometry>
    </visual>
  </link>
  <link name="front_right_wheel">
    <inertial>
      <mass value="12"/>
      <origin rpy="0  0  0" xyz="0  0  0"/>
      <inertia ixx="0.5" ixy="0.0" ixz="0.0" iyy="0.5" iyz="0.0" izz="1.0"/>
    </inertial>
    <collision name="collision">
      <origin rpy="0  0  0" xyz="0  0  0"/>
      <geometry>
        <cylinder length="0.2794" radius="0.3175"/>
      </geometry>
    </collision>
    <visual name="visual">
      <origin rpy="0  1.57079  0" xyz="0  0  -0.13"/>
      <geometry>
        <mesh filename="package://atvsim_description/models/ATV/meshes/Wheel_Front_Left.dae" scale="1.003700111 0.886200464 0.886200464"/>
      </geometry>
    </visual>
  </link>
  <link name="rear_left_wheel">
    <inertial>
      <mass value="12"/>
      <origin rpy="0  0  0" xyz="0  0  0"/>
      <inertia ixx="0.5" ixy="0.0" ixz="0.0" iyy="0.5" iyz="0.0" izz="1.0"/>
    </inertial>
    <collision name="collision">
      <origin rpy="0  0  0" xyz="0  0  0"/>
      <geometry>
        <cylinder length="0.2794" radius="0.3175"/>
      </geometry>
    </collision>
    <visual name="visual">
      <origin rpy="0      1.57079  0" xyz="0  0  -0.13"/>
      <geometry>
        <mesh filename="package://atvsim_description/models/ATV/meshes/Wheels_Rear_Left.dae" scale="1.003700111 0.886200464 0.886200464"/>
      </geometry>
    </visual>
  </link>
  <link name="rear_right_wheel">
    <inertial>
      <mass value="12"/>
      <origin rpy="0  0  0" xyz="0  0  0"/>
      <inertia ixx="0.5" ixy="0.0" ixz="0.0" iyy="0.5" iyz="0.0" izz="1.0"/>
    </inertial>
    <collision name="collision">
      <origin rpy="0  0  0" xyz="0  0  0"/>
      <geometry>
        <cylinder length="0.2794" radius="0.3175"/>
      </geometry>
    </collision>
    <visual name="visual">
      <origin rpy="0      -1.57079  0" xyz="0  0  -0.13"/>
      <geometry>
        <mesh filename="package://atvsim_description/models/ATV/meshes/Wheels_Rear_Right.dae" scale="1.003700111 0.886200464 0.886200464"/>
      </geometry>
    </visual>
  </link>
  <!-- <link name="gas_pedal">
    <inertial>
      <mass value="0.1"/>
      <origin rpy="0  0  0" xyz="0  0  0"/>
      <inertia ixx="0.01" ixy="0" ixz="0" iyy="0.01" iyz="0" izz="0.01"/>
    </inertial>
    <collision name="gas_pedal_collision">
      <origin rpy="3.14159  1.12559  3.14159" xyz="-0.0385  0     -0.086"/>
      <geometry>
        <box size="0.1069000 0.0770000 0.010000"/>
      </geometry>
    </collision>
    <visual name="visual">
      <origin rpy="0      0     -1.5707" xyz="0  0  0"/>
      <geometry>
        <mesh filename="package://atvsim_description/models/ATV/meshes/Gas_Pedal.dae" scale="1.0 1.0 1.0"/>
      </geometry>
    </visual>
  </link>
  <link name="brake_pedal">
    <inertial>
      <mass value="0.1"/>
      <origin rpy="0  0  0" xyz="0  0  0"/>
      <inertia ixx="0.01" ixy="0" ixz="0" iyy="0.01" iyz="0" izz="0.01"/>
    </inertial>
    <collision name="brake_pedal_collision">
      <origin rpy="3.14159  1.14259  3.14159" xyz="-0.04   0    -0.086"/>
      <geometry>
        <box size="0.063 0.08 0.01"/>
      </geometry>
    </collision>
    <visual name="visual">
      <origin rpy="0      0     -1.5707" xyz="0  0  0"/>
      <geometry>
        <mesh filename="package://atvsim_description/models/ATV/meshes/Brake_Pedal.dae" scale="1.0 1.0 1.0"/>
      </geometry>
    </visual>
  </link> -->
  <link name="front_right_wheel_steering_block">
    <inertial>
      <mass value="1"/>
      <origin rpy="0  0  0" xyz="0  0  0"/>
      <inertia ixx="1.0" ixy="0.0" ixz="0.0" iyy="1.0" iyz="0.0" izz="1.0"/>
    </inertial>
    <collision name="collision">
      <origin rpy="0  0  0" xyz="0  0  0"/>
      <geometry>
        <cylinder length="0.01" radius="0.05"/>
      </geometry>
    </collision>
  </link>
  <link name="front_left_wheel_steering_block">
    <inertial>
      <mass value="1"/>
      <origin rpy="0  0  0" xyz="0  0  0"/>
      <inertia ixx="1.0" ixy="0.0" ixz="0.0" iyy="1.0" iyz="0.0" izz="1.0"/>
    </inertial>
    <collision name="collision">
      <origin rpy="0  0  0" xyz="0  0  0"/>
      <geometry>
        <cylinder length="0.01" radius="0.05"/>
      </geometry>
    </collision>
  </link>
  <!-- <link name="steering_rod">
    <inertial>
      <mass value="1"/>
      <origin rpy="0  0  0" xyz="0  0  0"/>
      <inertia ixx="1.0" ixy="0.0" ixz="0.0" iyy="1.0" iyz="0.0" izz="1.0"/>
    </inertial>
    <collision name="collision">
      <origin rpy="3.14159  0  0" xyz="0  0  0"/>
      <geometry>
        <cylinder length="1" radius="0.01"/>
      </geometry>
    </collision>
    <visual name="tied_rod">
      <origin rpy="3.14159  0  0" xyz="0 0   0"/>
      <geometry>
        <cylinder length="1" radius="0.01"/>
      </geometry>
    </visual>
  </link> -->
  <link name="steering_rod_left_block">
    <inertial>
      <mass value="1"/>
      <origin rpy="0  0  0" xyz="0  0  0"/>
      <inertia ixx="1.0" ixy="0.0" ixz="0.0" iyy="1.0" iyz="0.0" izz="1.0"/>
    </inertial>
    <collision name="collision">
      <origin rpy="0 0    0" xyz="0  0  0.35"/>
      <geometry>
        <cylinder length="0.7" radius="0.01"/>
      </geometry>
    </collision>
    <visual name="tied_rod_left">
      <origin rpy="0 0  0" xyz="0 0   0.39"/>
      <geometry>
        <cylinder length="0.78" radius="0.01"/>
      </geometry>
    </visual>
  </link>
  <link name="steering_rod_right_block">
    <inertial>
      <mass value="1"/>
      <origin rpy="0  0  0" xyz="0  0  0"/>
      <inertia ixx="1.0" ixy="0.0" ixz="0.0" iyy="1.0" iyz="0.0" izz="1.0"/>
    </inertial>
    <collision name="collision">
      <origin rpy="0  0  0" xyz="0  0  0"/>
      <geometry>
        <cylinder length="0.1" radius="0.01"/>
      </geometry>
    </collision>
    <visual name="tied_rod_right">
      <origin rpy="0  0  0" xyz="0 0   0"/>
      <geometry>
        <cylinder length="0.1" radius="0.01"/>
      </geometry>
    </visual>
  </link>


  <joint name="hokuyo_joint" type="fixed">
    <axis xyz="0 1 0" />
    <origin xyz="1.2 0 1.2" rpy="0 0 0"/>
    <parent link="base_link"/>
    <child link="hokuyo_link"/>
  </joint>

  <!-- Hokuyo Laser -->
  <link name="hokuyo_link">
    <collision>
      <origin xyz="0 0 0" rpy="0 0 3.14159265"/>
      <geometry>
    <box size="0.1 0.1 0.1"/>
      </geometry>
    </collision>

    <visual>
      <origin xyz="0 0 0" rpy="0 0 0"/>
      <geometry>
        <mesh filename="package://atvsim_description/models/ATV/meshes/hokuyo.dae"/>
      </geometry>
    </visual>

    <inertial>
      <mass value="1e-5" />
      <origin xyz="0 0 0" rpy="0 0 0"/>
      <inertia ixx="1e-6" ixy="0" ixz="0" iyy="1e-6" iyz="0" izz="1e-6" />
    </inertial>
  </link>
  <!-- Camera -->
  <link name="camera_link">
    <inertial>
      <mass value="1e-5" />
      <origin xyz="0 0 0" rpy="0 0 0"/>
      <inertia ixx="1e-6" ixy="0" ixz="0" iyy="1e-6" iyz="0" izz="1e-6" />
    </inertial>
    <collision name="collision">
      <origin xyz="0 0 0" rpy="0 0 0"/>
      <geometry>
        <box size="0.05 0.05 0.05"/>
      </geometry>
    </collision>

    <visual name="camera_front">
      <origin xyz="0 0 0" rpy="0 0 0"/>
      <geometry>
        <box size="0.05 0.05 0.05"/>
      </geometry>
      <material name="red">
        <color rgba="1 0 0 1" />
      </material>
    </visual>
  </link>
  <!-- <link name="steering_wheel">
    <inertial>
      <mass value="1.0"/>
      <origin rpy="0  0  0" xyz="-0.002  0     0"/>
      <inertia ixx="0.012" ixy="0" ixz="0" iyy="0.012" iyz="0" izz="0.024"/>
    </inertial>
    <collision name="collision">
      <origin rpy="-0.6108   0      -1.57079" xyz="-0.03     0      -0.12082"/>
      <geometry>
        <mesh filename="package://atvsim_description/models/ATV/meshes/Steering_Wheel.dae" scale="1.0 1.0 1.0"/>
      </geometry>
    </collision>
    <visual name="visual">
      <origin rpy="-0.6108   0      -1.57079" xyz="-0.03     0      -0.12082"/>
      <geometry>
        <mesh filename="package://atvsim_description/models/ATV/meshes/Steering_Wheel.dae" scale="1.0 1.0 1.0"/>
      </geometry>
    </visual>
  </link>
  <link name="hand_brake">
    <inertial>
      <mass value="0.5"/>
      <origin rpy="0  0  0" xyz="0  0  0"/>
      <inertia ixx="0.1" ixy="0" ixz="0" iyy="0.1" iyz="0" izz="0.05"/>
    </inertial>
    <collision name="hand_brake_collision">
      <origin rpy="-0.2      0      -1.57079" xyz="0    0    0.05"/>
      <geometry>
        <mesh filename="package://atvsim_description/models/ATV/meshes/Shifter.dae" scale="1.0 1.0 1.0"/>
      </geometry>
    </collision>
    <visual name="hand_brake_visual">
      <origin rpy="-0.2      0      -1.57079" xyz="0    0    0.05"/>
      <geometry>
        <mesh filename="package://atvsim_description/models/ATV/meshes/Shifter.dae" scale="1.0 1.0 1.0"/>
      </geometry>
    </visual>
  </link>
  <link name="FNR_switch">
    <inertial>
      <mass value="0.1"/>
      <origin rpy="0  0  0" xyz="0  0  0"/>
      <inertia ixx="0.1" ixy="0" ixz="0" iyy="0.00006" iyz="0" izz="0.1"/>
    </inertial>
    <collision name="FNR_switch">
      <origin rpy="0  0  0" xyz="0  0  0"/>
      <geometry>
        <box size="0.02 0.04 0.08"/>
      </geometry>
    </collision>
    <visual name="FNR_switch_F">
      <origin rpy="0  0  0" xyz="0  0  0"/>
      <geometry>
        <box size="0.02 0.04 0.08"/>
      </geometry>
    </visual>
    <visual name="FNR_switch_R">
      <origin rpy="0  0  0" xyz="0  0  0"/>
      <geometry>
        <box size="0.0199 0.0399 0.0799"/>
      </geometry>
    </visual>
  </link> -->
  <gazebo reference="front_left_steering_joint">
    <axis>
      <dynamics>
        <damping>50.0</damping>
      </dynamics>
    </axis>
    <physics>
      <ode>
        <cfm_damping>1</cfm_damping>
        <limit>
          <cfm>0.000000</cfm>
          <erp>0.900000</erp>
        </limit>
      </ode>
    </physics>
  </gazebo>
  <gazebo reference="front_right_steering_joint">
    <axis>
      <dynamics>
        <damping>50.0</damping>
      </dynamics>
    </axis>
    <physics>
      <ode>
        <cfm_damping>1</cfm_damping>
        <limit>
          <cfm>0.000000</cfm>
          <erp>0.900000</erp>
        </limit>
      </ode>
    </physics>
  </gazebo>
  <!-- <gazebo reference="rear_differential_joint">
    <axis>
      <dynamics>
        <damping>70.0</damping>
      </dynamics>
    </axis>
    <physics>
      <ode>
        <erp>0</erp>
        <cfm>1000</cfm>
        <cfm_damping>1</cfm_damping>
      </ode>
    </physics>
  </gazebo> -->
  <gazebo reference="front_left_wheel">
    <pose>1.20223 0.71562 0.34697 -1.52 0.0 0.0</pose>
    <collision name="collision">
      <max_contacts>1</max_contacts>
      <surface>
        <friction>
          <ode>
            <mu>1.0</mu>
            <mu2>1.0</mu2>
            <fdir1>0 0 1</fdir1>
            <slip1>0.0</slip1>
            <slip2>0.0</slip2>
          </ode>
        </friction>
        <contact>
          <ode>
            <min_depth>0.005</min_depth>
            <kp>1e8</kp>
          </ode>
        </contact>
      </surface>
    </collision>
  </gazebo>
  <gazebo reference="front_right_wheel">
    <!-- <pose>1.20223 -0.71562 0.34697 1.52 0.0 0.0</pose> -->
    <collision name="collision">
      <max_contacts>1</max_contacts>
      <surface>
        <friction>
          <ode>
            <mu>1.0</mu>
            <mu2>1.0</mu2>
            <fdir1>0 0 1</fdir1>
            <slip1>0.0</slip1>
            <slip2>0.0</slip2>
          </ode>
        </friction>
        <contact>
          <ode>
            <min_depth>0.005</min_depth>
            <kp>1e8</kp>
          </ode>
        </contact>
      </surface>
    </collision>
  </gazebo>
  <gazebo reference="rear_left_wheel">
    <!-- <pose>1.20223 -0.71562 0.34697 1.52 0.0 0.0</pose> -->
    <collision name="collision">
      <max_contacts>1</max_contacts>
      <surface>
        <friction>
          <ode>
            <mu>1.0</mu>
            <mu2>1.0</mu2>
            <fdir1>0 0 1</fdir1>
            <slip1>0.0</slip1>
            <slip2>0.0</slip2>
          </ode>
        </friction>
        <contact>
          <ode>
            <min_depth>0.005</min_depth>
            <kp>1e8</kp>
          </ode>
        </contact>
      </surface>
    </collision>
  </gazebo>
  <gazebo reference="rear_right_wheel">
    <!-- <pose>1.20223 -0.71562 0.34697 1.52 0.0 0.0</pose> -->
    <collision name="collision">
      <max_contacts>1</max_contacts>
      <surface>
        <friction>
          <ode>
            <mu>1.0</mu>
            <mu2>1.0</mu2>
            <fdir1>0 0 1</fdir1>
            <slip1>0.0</slip1>
            <slip2>0.0</slip2>
          </ode>
        </friction>
        <contact>
          <ode>
            <min_depth>0.005</min_depth>
            <kp>1e8</kp>
          </ode>
        </contact>
      </surface>
    </collision>
  </gazebo>
  <!-- camera -->
  <gazebo reference="camera_link">
    <material>Gazebo/red</material>
    <sensor type="camera" name="camera1">
      <update_rate>30.0</update_rate>
      <camera name="head">
       <horizontal_fov>1.3962634</horizontal_fov>
       <image>
         <width>800</width>
         <height>800</height>
         <format>R8G8B8</format>
       </image>
       <clip>
         <near>0.02</near>
         <far>300</far>
       </clip>
       <noise>
         <type>gaussian</type>
         <mean>0.0</mean>
         <stddev>0.007</stddev>
       </noise>
     </camera>
      <plugin name="camera_controller" filename="libgazebo_ros_camera.so">
        <alwaysOn>true</alwaysOn>
        <updateRate>0.0</updateRate>
        <cameraName>front_camera</cameraName>
        <imageTopicName>front_image_raw</imageTopicName>
        <cameraInfoTopicName>front_camera_info</cameraInfoTopicName>
        <frameName>camera_link</frameName>
        <hackBaseline>0.07</hackBaseline>
        <distortionK1>0.0</distortionK1>
        <distortionK2>0.0</distortionK2>
        <distortionK3>0.0</distortionK3>
        <distortionT1>0.0</distortionT1>
        <distortionT2>0.0</distortionT2>
     </plugin>
   </sensor>
  </gazebo>
  <!-- hokuyo -->
  <gazebo reference="hokuyo_link">
    <sensor type="gpu_ray" name="head_hokuyo_sensor">
    <pose>0 0 0 0 0 0</pose>
    <visualize>false</visualize>
    <update_rate>40</update_rate>
    <ray>
      <scan>
        <horizontal>
          <samples>720</samples>
          <resolution>1</resolution>
          <min_angle>-1.57</min_angle>
          <max_angle>1.57</max_angle>
        </horizontal>
      </scan>
      <range>
        <min>0.10</min>
        <max>30.0</max>
        <resolution>0.01</resolution>
      </range>
      <noise>
        <type>gaussian</type>
        <mean>0.0</mean>
        <stddev>0.01</stddev>
      </noise>
    </ray>
    <plugin name="gazebo_ros_head_hokuyo_controller" filename="libgazebo_ros_gpu_laser.so">
      <topicName>scan</topicName>
      <frameName>hokuyo_link</frameName>
    </plugin>
  </sensor>
  </gazebo>
  <gazebo>
    <plugin name="gps_controller" filename="libhector_gazebo_ros_gps.so">
      <alwayson>true</alwayson>
      <!-- <frameID>fix</frameID> -->
      <updaterate>20</updaterate>
      <bodyname>base_link</bodyname>
      <topicname>fix</topicname>
      <velocitytopicname>fix_velocity</velocitytopicname>
      <referenceLatitude>37.228369</referenceLatitude>
      <referenceLongitude>-80.423045</referenceLongitude>
      <referenceHeading>90</referenceHeading>
      <drift>0 0 0</drift>
      <!-- <drift>1.0 1.0 1.0</drift> -->
      <gaussiannoise>0 0 0</gaussiannoise>
      <!-- <gaussiannoise>0.1 0.1 0.1</gaussiannoise> -->
      <velocitydrift>0 0 0</velocitydrift>
      <velocitygaussiannoise>0 0 0</velocitygaussiannoise>
      <!-- <velocitygaussiannoise>0.1 0.1 0.1</velocitygaussiannoise> -->
    </plugin>
    <plugin filename="libhector_gazebo_ros_imu.so" name="imu_plugin">
      <updateRate>200</updateRate>
      <bodyName>imu_link</bodyName>
      <topicName>imu</topicName>
      <serviceName>imu/calibrate</serviceName>
      <accelOffset>0.0 0.0 0.0</accelOffset>
      <accelDrift>0.0 0.0 0.0</accelDrift>
      <accelDriftFrequency>0.0 0.0 0.0</accelDriftFrequency>
      <accelGaussianNoise>0.0 0.0 0.0</accelGaussianNoise>
      <rateOffset>0.0 0.0 0.0</rateOffset>
      <rateDrift>0.0 0.0 0.0</rateDrift>
      <rateDriftFrequency>0.0 0.0 0.0</rateDriftFrequency>
      <rateGaussianNoise>0.0 0.0 0.0</rateGaussianNoise>
      <headingOffset>0.0</headingOffset>
      <headingDrift>0.0</headingDrift>
      <headingDriftFrequency>0.0</headingDriftFrequency>
      <headingGaussianNoise>0.0</headingGaussianNoise>
      <rpyOffset>0.0 0.0 0.0</rpyOffset>
      <xyzOffset>0.0 0.0 0.0</xyzOffset>
      <gaussianNoise>0.0</gaussianNoise>
      <yawOffset>-1.5708</yawOffset>
    </plugin>
    <plugin name="gazebo_ros_control" filename="libgazebo_ros_control.so">
      <robotNamespace>/</robotNamespace>
    </plugin>
    <plugin name="differential_drive_controller" filename="libgazebo_ros_diff_drive.so">
      <alwaysOn>true</alwaysOn>
      <updateRate>$50</updateRate>
      <leftJoint>rear_left_wheel_joint</leftJoint>
      <rightJoint>rear_right_wheel_joint</rightJoint>
      <wheelSeparation>1.43124</wheelSeparation>
      <wheelDiameter>0.635</wheelDiameter>
      <wheelTorque>300</wheelTorque>
      <commandTopic>rear_wheel_vel</commandTopic>
      <odometryTopic>odom_diff</odometryTopic>
      <odometryFrame>odom_diff</odometryFrame>
      <robotBaseFrame>base_link</robotBaseFrame>
      <publishOdomTF>false</publishOdomTF>
    </plugin>

  </gazebo>
  <!-- <transmission name="rear_wheel_left_trans">
    <type>transmission_interface/SimpleTransmission</type>
    <actuator name="$rear_wheel_left_motor">
      <mechanicalReduction>1</mechanicalReduction>
    </actuator>
    <joint name="rear_left_wheel_joint">
      <hardwareInterface>hardware_interface/EffortJointInterface</hardwareInterface>
    </joint>
  </transmission>
  <transmission name="rear_wheel_right_trans">
    <type>transmission_interface/SimpleTransmission</type>
    <actuator name="$rear_wheel_right_motor">
      <mechanicalReduction>1</mechanicalReduction>
    </actuator>
    <joint name="rear_right_wheel_joint">
      <hardwareInterface>hardware_interface/EffortJointInterface</hardwareInterface>
    </joint>
  </transmission> -->
  <transmission name="steering_trans">
    <type>transmission_interface/SimpleTransmission</type>
    <actuator name="$steering_motor">
      <mechanicalReduction>1</mechanicalReduction>
    </actuator>
    <joint name="front_right_steering_joint">
      <hardwareInterface>hardware_interface/PositionJointInterface</hardwareInterface>
    </joint>
  </transmission>
</robot>
